Traceback (most recent call last):
  File "/Users/emueller/opt/anaconda3/lib/python3.9/site-packages/jupyter_cache/executors/utils.py", line 58, in single_nb_execution
    executenb(
  File "/Users/emueller/opt/anaconda3/lib/python3.9/site-packages/nbclient/client.py", line 1305, in execute
    return NotebookClient(nb=nb, resources=resources, km=km, **kwargs).execute()
  File "/Users/emueller/opt/anaconda3/lib/python3.9/site-packages/jupyter_core/utils/__init__.py", line 165, in wrapped
    return loop.run_until_complete(inner)
  File "/Users/emueller/opt/anaconda3/lib/python3.9/asyncio/base_events.py", line 647, in run_until_complete
    return future.result()
  File "/Users/emueller/opt/anaconda3/lib/python3.9/site-packages/nbclient/client.py", line 705, in async_execute
    await self.async_execute_cell(
  File "/Users/emueller/opt/anaconda3/lib/python3.9/site-packages/nbclient/client.py", line 1058, in async_execute_cell
    await self._check_raise_for_error(cell, cell_index, exec_reply)
  File "/Users/emueller/opt/anaconda3/lib/python3.9/site-packages/nbclient/client.py", line 914, in _check_raise_for_error
    raise CellExecutionError.from_cell_and_msg(cell, exec_reply_content)
nbclient.exceptions.CellExecutionError: An error occurred while executing the following cell:
------------------
2*at
------------------


MethodError: no method matching *(::Int64, ::Tuple{Float64, Float64})

[0mClosest candidates are:
[0m  *(::Any, ::Any, [91m::Any[39m, [91m::Any...[39m)
[0m[90m   @[39m [90mBase[39m [90m[4moperators.jl:578[24m[39m
[0m  *(::T, [91m::T[39m) where T<:Union{Int128, Int16, Int32, Int64, Int8, UInt128, UInt16, UInt32, UInt64, UInt8}
[0m[90m   @[39m [90mBase[39m [90m[4mint.jl:88[24m[39m
[0m  *(::Union{Int16, Int32, Int64, Int8}, [91m::BigInt[39m)
[0m[90m   @[39m [90mBase[39m [90m[4mgmp.jl:552[24m[39m
[0m  ...


Stacktrace:
 [1] top-level scope
   @ In[26]:1

