Traceback (most recent call last):
  File "/Users/emueller/opt/anaconda3/lib/python3.9/site-packages/jupyter_cache/executors/utils.py", line 58, in single_nb_execution
    executenb(
  File "/Users/emueller/opt/anaconda3/lib/python3.9/site-packages/nbclient/client.py", line 1305, in execute
    return NotebookClient(nb=nb, resources=resources, km=km, **kwargs).execute()
  File "/Users/emueller/opt/anaconda3/lib/python3.9/site-packages/jupyter_core/utils/__init__.py", line 165, in wrapped
    return loop.run_until_complete(inner)
  File "/Users/emueller/opt/anaconda3/lib/python3.9/asyncio/base_events.py", line 647, in run_until_complete
    return future.result()
  File "/Users/emueller/opt/anaconda3/lib/python3.9/site-packages/nbclient/client.py", line 705, in async_execute
    await self.async_execute_cell(
  File "/Users/emueller/opt/anaconda3/lib/python3.9/site-packages/nbclient/client.py", line 1058, in async_execute_cell
    await self._check_raise_for_error(cell, cell_index, exec_reply)
  File "/Users/emueller/opt/anaconda3/lib/python3.9/site-packages/nbclient/client.py", line 914, in _check_raise_for_error
    raise CellExecutionError.from_cell_and_msg(cell, exec_reply_content)
nbclient.exceptions.CellExecutionError: An error occurred while executing the following cell:
------------------
d1=duffing()
------------------


UndefVarError: `ax` not defined

Stacktrace:
 [1] [0m[1mduffing[22m[0m[1m([22m; [90mxv[39m::[0mVector[90m{Float64}[39m, [90mp[39m::[0mdp, [90mt[39m::[0mFloat64, [90mdt[39m::[0mFloat64, [90mdelay[39m::[0mFloat64, [90mstep[39m::[0mFunction, [90mdxdt[39m::[0mFunction[0m[1m)[22m
[90m   @[39m [35mMain[39m [90m./[39m[90m[4mIn[4]:14[24m[39m
 [2] [0m[1mduffing[22m[0m[1m([22m[0m[1m)[22m
[90m   @[39m [35mMain[39m [90m./[39m[90m[4mIn[4]:1[24m[39m
 [3] top-level scope
[90m   @[39m [90m[4mIn[5]:1[24m[39m

