Traceback (most recent call last):
  File "/Users/emueller/opt/anaconda3/lib/python3.9/site-packages/jupyter_cache/executors/utils.py", line 58, in single_nb_execution
    executenb(
  File "/Users/emueller/opt/anaconda3/lib/python3.9/site-packages/nbclient/client.py", line 1305, in execute
    return NotebookClient(nb=nb, resources=resources, km=km, **kwargs).execute()
  File "/Users/emueller/opt/anaconda3/lib/python3.9/site-packages/jupyter_core/utils/__init__.py", line 165, in wrapped
    return loop.run_until_complete(inner)
  File "/Users/emueller/opt/anaconda3/lib/python3.9/asyncio/base_events.py", line 647, in run_until_complete
    return future.result()
  File "/Users/emueller/opt/anaconda3/lib/python3.9/site-packages/nbclient/client.py", line 705, in async_execute
    await self.async_execute_cell(
  File "/Users/emueller/opt/anaconda3/lib/python3.9/site-packages/nbclient/client.py", line 1058, in async_execute_cell
    await self._check_raise_for_error(cell, cell_index, exec_reply)
  File "/Users/emueller/opt/anaconda3/lib/python3.9/site-packages/nbclient/client.py", line 914, in _check_raise_for_error
    raise CellExecutionError.from_cell_and_msg(cell, exec_reply_content)
nbclient.exceptions.CellExecutionError: An error occurred while executing the following cell:
------------------
d1=duffing()
------------------


UndefVarError: `ax` not defined

Stacktrace:
 [1] duffing(; xv::Vector{Float64}, p::dp, t::Float64, dt::Float64, delay::Float64, step::Function, dxdt::Function)
   @ Main ./In[4]:14
 [2] duffing()
   @ Main ./In[4]:1
 [3] top-level scope
   @ In[5]:1

