Traceback (most recent call last):
  File "/Users/emueller/opt/anaconda3/lib/python3.9/site-packages/jupyter_cache/executors/utils.py", line 58, in single_nb_execution
    executenb(
  File "/Users/emueller/opt/anaconda3/lib/python3.9/site-packages/nbclient/client.py", line 1305, in execute
    return NotebookClient(nb=nb, resources=resources, km=km, **kwargs).execute()
  File "/Users/emueller/opt/anaconda3/lib/python3.9/site-packages/jupyter_core/utils/__init__.py", line 165, in wrapped
    return loop.run_until_complete(inner)
  File "/Users/emueller/opt/anaconda3/lib/python3.9/asyncio/base_events.py", line 647, in run_until_complete
    return future.result()
  File "/Users/emueller/opt/anaconda3/lib/python3.9/site-packages/nbclient/client.py", line 705, in async_execute
    await self.async_execute_cell(
  File "/Users/emueller/opt/anaconda3/lib/python3.9/site-packages/nbclient/client.py", line 1058, in async_execute_cell
    await self._check_raise_for_error(cell, cell_index, exec_reply)
  File "/Users/emueller/opt/anaconda3/lib/python3.9/site-packages/nbclient/client.py", line 914, in _check_raise_for_error
    raise CellExecutionError.from_cell_and_msg(cell, exec_reply_content)
nbclient.exceptions.CellExecutionError: An error occurred while executing the following cell:
------------------
x-0.25
------------------


MethodError: no method matching -(::Tuple{Int64, Int64, Int64}, ::Float64)

[0mClosest candidates are:
[0m  -([91m::Missing[39m, ::Number)
[0m[90m   @[39m [90mBase[39m [90m[4mmissing.jl:123[24m[39m
[0m  -([91m::BigFloat[39m, ::Union{Float16, Float32, Float64})
[0m[90m   @[39m [90mBase[39m [90m[4mmpfr.jl:506[24m[39m
[0m  -([91m::Complex{Bool}[39m, ::Real)
[0m[90m   @[39m [90mBase[39m [90m[4mcomplex.jl:326[24m[39m
[0m  ...


Stacktrace:
 [1] top-level scope
[90m   @[39m [90m[4mIn[24]:1[24m[39m

